{
    "CVE-ID": "CVE-2010-1634",
    "NVD": {
        "Descriptions": "Multiple integer overflows in audioop.c in the audioop module in Python 2.6, 2.7, 3.1, and 3.2 allow context-dependent attackers to cause a denial of service (application crash) via a large fragment, as demonstrated by a call to audioop.lin2lin with a long string in the first argument, leading to a buffer overflow.  NOTE: this vulnerability exists because of an incorrect fix for CVE-2008-3143.5.",
        "Cvss2_BaseScore": 5,
        "Cvss3_BaseScore": 0,
        "Cvss2_VectorString": "AV:N/AC:L/Au:N/C:N/I:N/A:P",
        "Cvss3_VectorString": "",
        "CPEs": [
            {
                "URI": "cpe:/a:python:python:3.2",
                "FormattedString": "cpe:2.3:a:python:python:3.2:*:*:*:*:*:*:*",
                "VersionStartExcluding": "",
                "VersionStartIncluding": "",
                "VersionEndExcluding": "",
                "VersionEndIncluding": ""
            },
            {
                "URI": "cpe:/a:python:python:3.1",
                "FormattedString": "cpe:2.3:a:python:python:3.1:*:*:*:*:*:*:*",
                "VersionStartExcluding": "",
                "VersionStartIncluding": "",
                "VersionEndExcluding": "",
                "VersionEndIncluding": ""
            }
        ]
    },
    "Official": {
        "2.5.6c1": {
            "source": [
                "https://github.com/python/cpython/blob/2.5/Misc/NEWS"
            ],
            "BTS": {
                "bpo8674": {
                    "ID": "bpo8674",
                    "url": "https://bugs.python.org/issue8674",
                    "date": "",
                    "nonce": "",
                    "section": ""
                }
            }
        },
        "2.7rc1": {
            "source": [
                "https://github.com/python/cpython/blob/v2.7.15rc1/Misc/NEWS.d/2.7rc1.rst"
            ],
            "BTS": {
                "bpo8674": {
                    "ID": "bpo8674",
                    "url": "https://bugs.python.org/issue8674",
                    "date": "8047",
                    "nonce": "Q2kfWX",
                    "section": "Library"
                }
            }
        },
        "2.6.6rc1": {
            "source": [
                "https://github.com/python/cpython/blob/2.6/Misc/NEWS"
            ],
            "BTS": {
                "bpo8674": {
                    "ID": "bpo8674",
                    "url": "https://bugs.python.org/issue8674",
                    "date": "",
                    "nonce": "",
                    "section": ""
                }
            }
        },
        "3.1.3rc1": {
            "source": [
                "https://github.com/python/cpython/blob/3.1/Misc/NEWS"
            ],
            "BTS": {
                "bpo8674": {
                    "ID": "bpo8674",
                    "url": "https://bugs.python.org/issue8674",
                    "date": "",
                    "nonce": "",
                    "section": ""
                }
            }
        },
        "3.2a1": {
            "source": [
                "https://github.com/python/cpython/blob/3.2/Misc/NEWS"
            ],
            "BTS": {
                "bpo8674": {
                    "ID": "bpo8674",
                    "url": "https://bugs.python.org/issue8674",
                    "date": "",
                    "nonce": "",
                    "section": ""
                }
            }
        }
    }
}